Workbook

Sheet Antecedentes
A7: Cotizacion N°: | B7: 513.1
A8: Empresa: | B8: Agrícola Peumo Ltda.
A9: Rut:
A10: Correo: | B10: aaravena@grupobrota.com
A11: Nombre Contacto: | B11: Adolfo Aravena
A12: Telefono:
A13: Tipo Proyecto: | B13: Llave en Mano Rafia
A14: Especie: | B14: Cerezas
A15: Sup. A Cotizar Há: | B15: =+'Cotizador de Insumos'!D2 -> 13.1848

Sheet Diseño estructura &CP
H2: * | I2: NO MODIFICAR NINGUN PARAMETRO DENTRO DEL ESQUEMA SOLO EN DATOS | AN2: PARAMETROS | BZ2: PERIMETRO FRONTAL
H3: * | I3: NO MODIFICAR NINGUN PARAMETRO DENTRO DEL ESQUEMA SOLO EN DATOS | AN3: Largo poste | AO3: 5 | AP3: Metros | AX3: Parámetros de alambres | BA3: Parámetros de Madera
AN4: Enterrado central | AO4: 0.8 | AP4: Metros | AX4: Nombre | AY4: tipo de alambre | AZ4: mts x rollo | BA4: Tipo | BB4: Nombre
AN5: Caída de agua | AO5: 0.8 | AP5: Metros | AX5: Cumbreras | AY5: Piola 4mm | AZ5: 1000 | BA5: Central | BB5: Polin4a5''x5mts
G6: Diseño de Estructura Recomendada | AN6: Corte Superior | AO6: 0.1 | AP6: Metros | AX6: Perímetro | AY6: Perimetro piola 6mm | AZ6: 500 | BA6: Cabezal | BB6: 5 a 6"x5mts
AN7: Ancho de lámina | AO7: 2 | AP7: Metros | AX7: Hombros | AY7: Piola 4mm | AZ7: 1000 | BA7: Cabezal Transversal | BB7: 5 a 6"x 4,5mts
AN8: recorrido elastico | AO8: 0.1 | AP8: Metros | AX8: TRANS. | AY8: Transversal piola 5 mm | AZ8: 500 | BA8: Esquinero | BB8: 6 a 7"x 4,5mt
AN9: Ancho entre hilera | AO9: =AO11 -> 4 | AP9: Metros | AX9: Guatana C | AY9: dulce 10 | AZ9: 700 | BA9: Yugo | BB9: 2 a 3"x2,4mts (60cm)
AN10: Largo de carpa | AO10: 12 | AP10: Metros | AX10: Guatana P | AY10: dulce 8 | AZ10: 480
AF11: =+AE12+AO8&"m" -> 2,1m | AJ11: =AO3-AO4 -> 4.2 | AN11: Distancia entre hileras | AO11: 4 | AX11: Riendas | AY11: Piola 6 mm | AZ11: 500
L12: m | O12: =AO7 -> 2 | P12: m | W12: =+AO7 -> 2 | X12: m | AE12: =O12 -> 2 | AF12: m | AN12: Distancia sobre hileras | AO12: 2 | AX12: Formación 1 | AY12: ALAMBRE 17/15 | AZ12: 1100
F13: =+AF11 -> 2,1m | L13: =AO5 -> 0.8 | AX13: Formación 2 | AY13: ALAMBRE N°12 BCC | AZ13: 1050
H14: Rafia | N14: Rafia | X14: Rafia | AD14: Rafia | AQ14: =3.5/2 -> 1.75 | AX14: Formación 3 | AY14: ALAMBRE DEL N°11 | AZ14: 1596
Q15: 0,1m | U15: 0,1m | AG15: 0,1m
M17: =AR22 -> 1.9416488 | R17: =(AO11-(M17+X17)) -> 0.11670243 | X17: =M17 -> 1.9416488
M18: m | S18: m | X18: m
AQ19: Cálculo
AQ20: largo hipotenusa | AR20: =AO6+AO7 -> 2.1 | AS20: m | AY20: Hip
AK21: mts | AQ21: largo cateto 1 | AR21: =AO5 -> 0.8 | AS21: m | AV21: Cat 1
AD22: m | AQ22: Largo cateto 2 | AR22: =SQRT((AR20*AR20)-(AR21*AR21)) -> 1.9416488 | AS22: m
AD23: =(AO3-AO4-AO5-AO6) -> 3.3
AY25: Cat 2
AQ28: Diseño de cobertor
AQ30: Ancho 2,2 mts | BZ30: PERIMETRO LATERAL
AQ31: Largo 10 mts
R33: =AO9 -> 4 | U33: m
F36: ="Diseño con cobertor de "&AO10&"m"&" con 10 cm de recorrido de elástico." -> Diseño con cobertor de 12m con 10 cm de recorrido de elástico.
CC53: * | CD53: Nota: Medidas Referenciales

Sheet Datos
B7: Especie: | C7: =+Antecedentes!$B$14 -> Cerezas | E7: Marco plantación | G7: Marco de Plantación Modificable | V7: Especie: | W7: =+Antecedentes!$B$14 -> Cerezas | Y7: Marco plantación | AA7: Marco de Plantación Modificable | AP7: Especie: | AQ7: =+Antecedentes!$B$14 -> Cerezas | AS7: Marco plantación | AU7: Marco de Plantación Modificable | BJ7: Especie: | BK7: =+Antecedentes!$B$14 -> Cerezas | BM7: Marco plantación | BO7: Marco de Plantación Modificable | CD7: Especie: | CE7: =+Antecedentes!$B$14 -> Cerezas | CG7: Marco plantación | CI7: Marco de Plantación Modificable | CX7: Especie: | CY7: =+Antecedentes!$B$14 -> Cerezas | DA7: Marco plantación | DC7: Marco de Plantación Modificable | DR7: Especie: | DS7: =+Antecedentes!$B$14 -> Cerezas | DU7: Marco plantación | DW7: Marco de Plantación Modificable | EL7: Especie: | EM7: =+Antecedentes!$B$14 -> Cerezas | EO7: Marco plantación | EQ7: Marco de Plantación Modificable | FF7: Especie: | FG7: =+Antecedentes!$B$14 -> Cerezas | FI7: Marco plantación | FK7: Marco de Plantación Modificable | FZ7: Especie: | GA7: =+Antecedentes!$B$14 -> Cerezas | GC7: Marco plantación | GE7: Marco de Plantación Modificable
B8: Variedad: | C8: Santina | E8: Entre hileras: | F8: 4 | G8: Entre Hileras | H8: Sobre Hileras | V8: Variedad: | W8: Santina | Y8: Entre hileras: | Z8: 4 | AA8: Entre Hileras | AB8: Sobre Hileras | AP8: Variedad: | AQ8: Santina | AS8: Entre hileras: | AT8: 4 | AU8: Entre Hileras | AV8: Sobre Hileras | BJ8: Variedad: | BM8: Entre hileras: | BN8: 4.5 | BO8: Entre Hileras | BP8: Sobre Hileras | CD8: Variedad: | CG8: Entre hileras: | CI8: Entre Hileras | CJ8: Sobre Hileras | CX8: Variedad: | DA8: Entre hileras: | DC8: Entre Hileras | DD8: Sobre Hileras | DR8: Variedad: | DU8: Entre hileras: | DW8: Entre Hileras | DX8: Sobre Hileras | EL8: Variedad: | EO8: Entre hileras: | EQ8: Entre Hileras | ER8: Sobre Hileras | FF8: Variedad: | FI8: Entre hileras: | FK8: Entre Hileras | FL8: Sobre Hileras | FZ8: Variedad: | GC8: Entre hileras: | GE8: Entre Hileras | GF8: Sobre Hileras
B9: Superficie (Ha): | C9: =+(F8*E14)/10000 -> 4.0938 | E9: Entre plantas: | F9: 2 | G9: 4 | H9: 2 | V9: Superficie (Ha): | W9: =+(Z8*Y14)/10000 -> 2.7578 | Y9: Entre plantas: | Z9: 2 | AA9: 4 | AB9: 2 | AP9: Superficie (Ha): | AQ9: =+(AT8*AS14)/10000 -> 4.5044 | AS9: Entre plantas: | AT9: 2 | AU9: 4 | AV9: 2 | BJ9: Superficie (Ha): | BK9: =+(BN8*BM14)/10000 -> 1.8288 | BM9: Entre plantas: | BN9: 2.2 | BO9: 4.5 | BP9: 2.2 | CD9: Superficie (Ha): | CE9: =+(CH8*CG14)/10000 -> 0 | CG9: Entre plantas: | CX9: Superficie (Ha): | CY9: =+(DB8*DA14)/10000 -> 0 | DA9: Entre plantas: | DR9: Superficie (Ha): | DS9: =+(DV8*DU14)/10000 -> 0 | DU9: Entre plantas: | EL9: Superficie (Ha): | EM9: =+(EP8*EO14)/10000 -> 0 | EO9: Entre plantas: | FF9: Superficie (Ha): | FG9: =+(FJ8*FI14)/10000 -> 0 | FI9: Entre plantas: | FZ9: Superficie (Ha): | GA9: =+(GD8*GC14)/10000 -> 0 | GC9: Entre plantas:
B10: Altura de plantas (m): | C10: =+C9/4 -> 1.02345 | G10: Nombre cuartel | H10: UTILIZACION DE CUARTEL | J10: PERIMETRO | P10: TRANSVERSAL | V10: Altura de plantas (m): | W10: =+W9/4 -> 0.68945 | AA10: Nombre cuartel | AB10: UTILIZACION DE CUARTEL | AD10: PERIMETRO | AJ10: TRANSVERSAL | AP10: Altura de plantas (m): | AQ10: =+AQ9/4 -> 1.1261 | AU10: Nombre cuartel | AV10: UTILIZACION DE CUARTEL | AX10: PERIMETRO | BD10: TRANSVERSAL | BJ10: Altura de plantas (m): | BK10: =+BK9/4 -> 0.4572 | BO10: Nombre cuartel | BP10: UTILIZACION DE CUARTEL | BR10: PERIMETRO | BX10: TRANSVERSAL | CD10: Altura de plantas (m): | CE10: =+CE9/4 -> 0 | CI10: Nombre cuartel | CJ10: UTILIZACION DE CUARTEL | CL10: PERIMETRO | CR10: TRANSVERSAL | CX10: Altura de plantas (m): | CY10: =+CY9/4 -> 0 | DC10: Nombre cuartel | DD10: UTILIZACION DE CUARTEL | DF10: PERIMETRO | DL10: TRANSVERSAL | DR10: Altura de plantas (m): | DS10: =+DS9/4 -> 0 | DW10: Nombre cuartel | DX10: UTILIZACION DE CUARTEL | DZ10: PERIMETRO | EF10: TRANSVERSAL | EL10: Altura de plantas (m): | EM10: =+EM9/4 -> 0 | EQ10: Nombre cuartel | ER10: UTILIZACION DE CUARTEL | ET10: PERIMETRO | EZ10: TRANSVERSAL | FF10: Altura de plantas (m): | FG10: =+FG9/4 -> 0 | FK10: Nombre cuartel | FL10: UTILIZACION DE CUARTEL | FN10: PERIMETRO | FT10: TRANSVERSAL | FZ10: Altura de plantas (m): | GA10: =+GA9/4 -> 0 | GE10: Nombre cuartel | GF10: UTILIZACION DE CUARTEL | GH10: PERIMETRO | GN10: TRANSVERSAL
G11: sector 1 | H11: SI | AA11: sector 2 | AB11: SI | AU11: sector 3 | AV11: SI | BO11: sector 4 | BP11: SI | CI11: sector 5 | CJ11: NO | DC11: sector 6 | DD11: NO | DW11: sector 7 | DX11: NO | EQ11: sector 8 | ER11: NO | FK11: sector 9 | FL11: NO | GE11: sector 10 | GF11: NO
B12: N° de Cuartel | C12: 1 | F12: 0 | R12: 1 | S12: cant de cortadas | V12: N° de Cuartel | W12: 2 | Z12: 0 | AL12: 1 | AM12: cant de cortadas | AP12: N° de Cuartel | AQ12: 3 | AT12: 0 | BF12: 1 | BG12: cant de cortadas | BJ12: N° de Cuartel | BK12: 4 | BN12: 0 | BZ12: 1 | CA12: cant de cortadas | CD12: N° de Cuartel | CE12: 5 | CH12: 0 | CT12: 1 | CU12: cant de cortadas | CX12: N° de Cuartel | CY12: 6 | DB12: 0 | DN12: 1 | DO12: cant de cortadas | DR12: N° de Cuartel | DS12: 7 | DV12: 0 | EH12: 1 | EI12: cant de cortadas | EL12: N° de Cuartel | EM12: 8 | EP12: 0 | FB12: 1 | FC12: cant de cortadas | FF12: N° de Cuartel | FG12: 9 | FJ12: 0 | FV12: 1 | FW12: cant de cortadas | FZ12: N° de Cuartel | GA12: 10 | GD12: 0 | GP12: 1 | GQ12: cant de cortadas
B13: Distancia centrales | C13: 12 | E13: metros | F13: Mts Camino central | H13: =F14+AB14 -> 906 | K13: =IF(H11="SI",ROUNDUP(K14/'Diseño estructura &CP'!$AZ$6,0),0) -> 3 | Q13: =COUNT(Q16:Q75) -> 23 | R13: =+Q13 -> 23 | S13: cant transversales | V13: Distancia centrales | W13: 12 | Y13: metros | Z13: Mts Camino central | AA13: 5 | AE13: =IF(AB11="SI",ROUNDUP(AE14/'Diseño estructura &CP'!$AZ$6,0),0) -> 2 | AK13: =COUNT(AK16:AK75) -> 16 | AL13: =IF(AB11="SI",COUNTA(AJ16:AJ150)*AL12,0) -> 16 | AM13: cant transversales | AP13: Distancia centrales | AQ13: 12 | AS13: metros | AT13: Mts Camino central | AY13: =IF(AV11="SI",ROUNDUP(AY14/'Diseño estructura &CP'!$AZ$6,0),0) -> 3 | BE13: =COUNT(BE16:BE75) -> 14 | BF13: =IF(AV11="SI",COUNTA(BD16:BD150)*BF12,0) -> 14 | BG13: cant transversales | BJ13: Distancia centrales | BK13: 11 | BM13: metros | BN13: Mts Camino central | BS13: =IF(BP11="SI",ROUNDUP(BS14/'Diseño estructura &CP'!$AZ$6,0),0) -> 2 | BY13: =COUNT(BY16:BY75) -> 18 | BZ13: =IF(BP11="SI",COUNTA(BX16:BX150)*BZ12,0) -> 18 | CA13: cant transversales | CD13: Distancia centrales | CG13: metros | CH13: Mts Camino central | CM13: =IF(CJ11="SI",ROUNDUP(CM14/'Diseño estructura &CP'!$AZ$6,0),0) -> 0 | CS13: =COUNT(CS16:CS75) -> 0 | CT13: =IF(CJ11="SI",COUNTA(CR16:CR150)*CT12,0) -> 0 | CU13: cant transversales | CX13: Distancia centrales | DA13: metros | DB13: Mts Camino central | DG13: =IF(DD11="SI",ROUNDUP(DG14/'Diseño estructura &CP'!$AZ$6,0),0) -> 0 | DM13: =COUNT(DM16:DM75) -> 0 | DN13: =IF(DD11="SI",COUNTA(DL16:DL150)*DN12,0) -> 0 | DO13: cant transversales | DR13: Distancia centrales | DU13: metros | DV13: Mts Camino central | EA13: =IF(DX11="SI",ROUNDUP(EA14/'Diseño estructura &CP'!$AZ$6,0),0) -> 0 | EG13: =COUNT(EG16:EG75) -> 0 | EH13: =IF(DX11="SI",COUNTA(EF16:EF150)*EH12,0) -> 0 | EI13: cant transversales | EL13: Distancia centrales | EO13: metros | EP13: Mts Camino central | EU13: =IF(ER11="SI",ROUNDUP(EU14/'Diseño estructura &CP'!$AZ$6,0),0) -> 0 | FA13: =COUNT(FA16:FA75) -> 0 | FB13: =IF(ER11="SI",COUNTA(EZ16:EZ150)*FB12,0) -> 0 | FC13: cant transversales | FF13: Distancia centrales | FI13: metros | FJ13: Mts Camino central | FO13: =IF(FL11="SI",ROUNDUP(FO14/'Diseño estructura &CP'!$AZ$6,0),0) -> 0 | FU13: =COUNT(FU16:FU75) -> 0 | FV13: =IF(FL11="SI",COUNTA(FT16:FT150)*FV12,0) -> 0 | FW13: cant transversales | FZ13: Distancia centrales | GC13: metros | GD13: Mts Camino central | GI13: =IF(GF11="SI",ROUNDUP(GI14/'Diseño estructura &CP'!$AZ$6,0),0) -> 0 | GO13: =COUNT(GO16:GO75) -> 0 | GP13: =IF(GF11="SI",COUNTA(GN16:GN150)*GP12,0) -> 0 | GQ13: cant transversales
B14: =MAX(B16:B265) -> 106 | C14: =IF($H$11="SI",SUMIF(C16:C265,">"&0,C16:C265),0) -> 5117.25 | D14: =IF($H$11="SI",SUMIF(D16:D265,">"&0,D16:D265),0) -> 801 | E14: =IF($H$11="SI",SUMIF(E16:E265,">"&0,E16:E265),0) -> 10234.5 | F14: =IF($H$11="SI",SUMIF(F16:F265,">"&0,F16:F265),0) -> 906 | G14: =IF($H$11="SI",SUMIF(G16:G265,">"&0,G16:G265)+1,0) -> 11.820076 | J14: Total | K14: =+SUM(K16:K48) -> 1168 | M14: =IF(H11="SI",ROUNDUP(K14/'Diseño estructura &CP'!$AZ$6,0),0) -> 3 | P14: Total | R14: =SUM(R16:R75) -> 9752 | S14: =ROUNDUP((R14/'Diseño estructura &CP'!$AZ$6),0) -> 20 | V14: =MAX(V16:V265) -> 55 | W14: =IF($H$11="SI",SUMIF(W16:W265,">"&0,W16:W265),0) -> 3447.25 | X14: =IF($H$11="SI",SUMIF(X16:X265,">"&0,X16:X265),0) -> 547 | Y14: =IF($H$11="SI",SUMIF(Y16:Y265,">"&0,Y16:Y265),0) -> 6894.5 | Z14: =IF($H$11="SI",SUMIF(Z16:Z265,">"&0,Z16:Z265),0) -> 600 | AA14: =IF($H$11="SI",SUMIF(AA16:AA265,">"&0,AA16:AA265)+1,0) -> 8.5296364 | AD14: Total | AE14: =+SUM(AE16:AE48) -> 818 | AG14: =IF(AB11="SI",ROUNDUP(AE14/'Diseño estructura &CP'!$AZ$6,0),0) -> 2 | AJ14: Total | AL14: =SUM(AL16:AL75) -> 3520 | AM14: =ROUNDUP((AL14/'Diseño estructura &CP'!$AZ$6),0) -> 8 | AP14: =MAX(AP16:AP265) -> 76 | AQ14: =IF($H$11="SI",SUMIF(AQ16:AQ265,">"&0,AQ16:AQ265),0) -> 5630.5 | AR14: =IF($H$11="SI",SUMIF(AR16:AR265,">"&0,AR16:AR265),0) -> 901 | AS14: =IF($H$11="SI",SUMIF(AS16:AS265,">"&0,AS16:AS265),0) -> 11261 | AT14: =IF($H$11="SI",SUMIF(AT16:AT265,">"&0,AT16:AT265),0) -> 977 | AU14: =IF($H$11="SI",SUMIF(AU16:AU265,">"&0,AU16:AU265)+1,0) -> 12.605107 | AX14: Total | AY14: =+SUM(AY16:AY48) -> 1102 | BA14: =IF(AV11="SI",ROUNDUP(AY14/'Diseño estructura &CP'!$AZ$6,0),0) -> 3 | BD14: Total | BF14: =SUM(BF16:BF75) -> 4256 | BG14: =ROUNDUP((BF14/'Diseño estructura &CP'!$AZ$6),0) -> 9 | BJ14: =MAX(BJ16:BJ265) -> 30 | BK14: =IF($H$11="SI",SUMIF(BK16:BK265,">"&0,BK16:BK265),0) -> 2032 | BL14: =IF($H$11="SI",SUMIF(BL16:BL265,">"&0,BL16:BL265),0) -> 355 | BM14: =IF($H$11="SI",SUMIF(BM16:BM265,">"&0,BM16:BM265),0) -> 4064 | BN14: =IF($H$11="SI",SUMIF(BN16:BN265,">"&0,BN16:BN265),0) -> 385 | BO14: =IF($H$11="SI",SUMIF(BO16:BO265,">"&0,BO16:BO265)+1,0) -> 5.2494061 | BR14: Total | BS14: =+SUM(BS16:BS48) -> 809.5 | BU14: =IF(BP11="SI",ROUNDUP(BS14/'Diseño estructura &CP'!$AZ$6,0),0) -> 2 | BX14: Total | BZ14: =SUM(BZ16:BZ75) -> 2160 | CA14: =ROUNDUP((BZ14/'Diseño estructura &CP'!$AZ$6),0) -> 5 | CD14: =MAX(CD16:CD265) -> 0 | CE14: =IF($H$11="SI",SUMIF(CE16:CE265,">"&0,CE16:CE265),0) -> 0 | CF14: =IF($H$11="SI",SUMIF(CF16:CF265,">"&0,CF16:CF265),0) -> 0 | CG14: =IF($H$11="SI",SUMIF(CG16:CG265,">"&0,CG16:CG265),0) -> 0 | CH14: =IF($H$11="SI",SUMIF(CH16:CH265,">"&0,CH16:CH265),0) -> 0 | CI14: =IF($H$11="SI",SUMIF(CI16:CI265,">"&0,CI16:CI265)+1,0) -> 1 | CL14: Total | CM14: =+SUM(CM16:CM48) -> 0 | CO14: =IF(CJ11="SI",ROUNDUP(CM14/'Diseño estructura &CP'!$AZ$6,0),0) -> 0 | CR14: Total | CT14: =SUM(CT16:CT75) -> 0 | CU14: =ROUNDUP((CT14/'Diseño estructura &CP'!$AZ$6),0) -> 0 | CX14: =MAX(CX16:CX265) -> 0 | CY14: =IF($H$11="SI",SUMIF(CY16:CY265,">"&0,CY16:CY265),0) -> 0 | CZ14: =IF($H$11="SI",SUMIF(CZ16:CZ265,">"&0,CZ16:CZ265),0) -> 0 | DA14: =IF($H$11="SI",SUMIF(DA16:DA265,">"&0,DA16:DA265),0) -> 0 | DB14: =IF($H$11="SI",SUMIF(DB16:DB265,">"&0,DB16:DB265),0) -> 0 | DC14: =IF($H$11="SI",SUMIF(DC16:DC265,">"&0,DC16:DC265)+1,0) -> 1 | DF14: Total | DG14: =+SUM(DG16:DG48) -> 0 | DI14: =IF(DD11="SI",ROUNDUP(DG14/'Diseño estructura &CP'!$AZ$6,0),0) -> 0 | DL14: Total | DN14: =SUM(DN16:DN75) -> 0 | DO14: =ROUNDUP((DN14/'Diseño estructura &CP'!$AZ$6),0) -> 0 | DR14: =MAX(DR16:DR265) -> 0 | DS14: =IF($H$11="SI",SUMIF(DS16:DS265,">"&0,DS16:DS265),0) -> 0 | DT14: =IF($H$11="SI",SUMIF(DT16:DT265,">"&0,DT16:DT265),0) -> 0 | DU14: =IF($H$11="SI",SUMIF(DU16:DU265,">"&0,DU16:DU265),0) -> 0 | DV14: =IF($H$11="SI",SUMIF(DV16:DV265,">"&0,DV16:DV265),0) -> 0 | DW14: =IF($H$11="SI",SUMIF(DW16:DW265,">"&0,DW16:DW265)+1,0) -> 1 | DZ14: Total | EA14: =+SUM(EA16:EA48) -> 0 | EC14: =IF(DX11="SI",ROUNDUP(EA14/'Diseño estructura &CP'!$AZ$6,0),0) -> 0 | EF14: Total | EH14: =SUM(EH16:EH75) -> 0 | EI14: =ROUNDUP((EH14/'Diseño estructura &CP'!$AZ$6),0) -> 0 | EL14: =MAX(EL16:EL265) -> 0 | EM14: =IF($H$11="SI",SUMIF(EM16:EM265,">"&0,EM16:EM265),0) -> 0 | EN14: =IF($H$11="SI",SUMIF(EN16:EN265,">"&0,EN16:EN265),0) -> 0 | EO14: =IF($H$11="SI",SUMIF(EO16:EO265,">"&0,EO16:EO265),0) -> 0 | EP14: =IF($H$11="SI",SUMIF(EP16:EP265,">"&0,EP16:EP265),0) -> 0 | EQ14: =IF($H$11="SI",SUMIF(EQ16:EQ265,">"&0,EQ16:EQ265)+1,0) -> 1 | ET14: Total | EU14: =+SUM(EU16:EU48) -> 0 | EW14: =IF(ER11="SI",ROUNDUP(EU14/'Diseño estructura &CP'!$AZ$6,0),0) -> 0 | EZ14: Total | FB14: =SUM(FB16:FB75) -> 0 | FC14: =ROUNDUP((FB14/'Diseño estructura &CP'!$AZ$6),0) -> 0 | FF14: =MAX(FF16:FF265) -> 0 | FG14: =IF($H$11="SI",SUMIF(FG16:FG265,">"&0,FG16:FG265),0) -> 0 | FH14: =IF($H$11="SI",SUMIF(FH16:FH265,">"&0,FH16:FH265),0) -> 0 | FI14: =IF($H$11="SI",SUMIF(FI16:FI265,">"&0,FI16:FI265),0) -> 0 | FJ14: =IF($H$11="SI",SUMIF(FJ16:FJ265,">"&0,FJ16:FJ265),0) -> 0 | FK14: =IF($H$11="SI",SUMIF(FK16:FK265,">"&0,FK16:FK265)+1,0) -> 1 | FN14: Total | FO14: =+SUM(FO16:FO48) -> 0 | FQ14: =IF(FL11="SI",ROUNDUP(FO14/'Diseño estructura &CP'!$AZ$6,0),0) -> 0 | FT14: Total | FV14: =SUM(FV16:FV75) -> 0 | FW14: =ROUNDUP((FV14/'Diseño estructura &CP'!$AZ$6),0) -> 0 | FZ14: =MAX(FZ16:FZ265) -> 0 | GA14: =IF($H$11="SI",SUMIF(GA16:GA265,">"&0,GA16:GA265),0) -> 0 | GB14: =IF($H$11="SI",SUMIF(GB16:GB265,">"&0,GB16:GB265),0) -> 0 | GC14: =IF($H$11="SI",SUMIF(GC16:GC265,">"&0,GC16:GC265),0) -> 0 | GD14: =IF($H$11="SI",SUMIF(GD16:GD265,">"&0,GD16:GD265),0) -> 0 | GE14: =IF($H$11="SI",SUMIF(GE16:GE265,">"&0,GE16:GE265)+1,0) -> 1 | GH14: Total | GI14: =+SUM(GI16:GI48) -> 0 | GK14: =IF(GF11="SI",ROUNDUP(GI14/'Diseño estructura &CP'!$AZ$6,0),0) -> 0 | GN14: Total | GP14: =SUM(GP16:GP75) -> 0 | GQ14: =ROUNDUP((GP14/'Diseño estructura &CP'!$AZ$6),0) -> 0
B15: N° hilera | C15: N° plantas | D15: Centrales | E15: Largo (m) | F15: Carpas | G15: Aprovechamiento | H15: hebras por rollo | J15: Perímetro | M15: Aprovechamiento | N15: hebras por rollo | P15: Transversal | R15: =IF(H11="SI",F8,0) -> 4 | S15: Aprovechamiento | T15: hebras por rollo | V15: N° hilera | W15: N° plantas | X15: Centrales | Y15: Largo (m) | Z15: Carpas | AA15: Aprovechamiento | AB15: hebras por rollo | AD15: Perímetro | AG15: Aprovechamiento | AH15: hebras por rollo | AJ15: Transversal | AL15: =IF(AB11="SI",Z8,0) -> 4 | AM15: Aprovechamiento | AN15: hebras por rollo | AP15: N° hilera | AQ15: N° plantas | AR15: Centrales | AS15: Largo (m) | AT15: Carpas | AU15: Aprovechamiento | AV15: hebras por rollo | AX15: Perímetro | BA15: Aprovechamiento | BB15: hebras por rollo | BD15: Transversal | BF15: =IF(AV11="SI",AT8,0) -> 4 | BG15: Aprovechamiento | BH15: hebras por rollo | BJ15: N° hilera | BK15: N° plantas | BL15: Centrales | BM15: Largo (m) | BN15: Carpas | BO15: Aprovechamiento | BP15: hebras por rollo | BR15: Perímetro | BU15: Aprovechamiento | BV15: hebras por rollo | BX15: Transversal | BZ15: =IF(BP11="SI",BN8,0) -> 4.5 | CA15: Aprovechamiento | CB15: hebras por rollo | CD15: N° hilera | CE15: N° plantas | CF15: Centrales | CG15: Largo (m) | CH15: Carpas | CI15: Aprovechamiento | CJ15: hebras por rollo | CL15: Perímetro | CO15: Aprovechamiento | CP15: hebras por rollo | CR15: Transversal | CT15: =IF(CJ11="SI",CH8,0) -> 0 | CU15: Aprovechamiento | CV15: hebras por rollo | CX15: N° hilera | CY15: N° plantas | CZ15: Centrales | DA15: Largo (m) | DB15: Carpas | DC15: Aprovechamiento | DD15: hebras por rollo | DF15: Perímetro | DI15: Aprovechamiento | DJ15: hebras por rollo | DL15: Transversal | DN15: =IF(DD11="SI",DB8,0) -> 0 | DO15: Aprovechamiento | DP15: hebras por rollo | DR15: N° hilera | DS15: N° plantas | DT15: Centrales | DU15: Largo (m) | DV15: Carpas | DW15: Aprovechamiento | DX15: hebras por rollo | DZ15: Perímetro | EC15: Aprovechamiento | ED15: hebras por rollo | EF15: Transversal | EH15: =IF(DX11="SI",DV8,0) -> 0 | EI15: Aprovechamiento | EJ15: hebras por rollo | EL15: N° hilera | EM15: N° plantas | EN15: Centrales | EO15: Largo (m) | EP15: Carpas | EQ15: Aprovechamiento | ER15: hebras por rollo | ET15: Perímetro | EW15: Aprovechamiento | EX15: hebras por rollo | EZ15: Transversal | FB15: =IF(ER11="SI",EP8,0) -> 0 | FC15: Aprovechamiento | FD15: hebras por rollo | FF15: N° hilera | FG15: N° plantas | FH15: Centrales | FI15: Largo (m) | FJ15: Carpas | FK15: Aprovechamiento | FL15: hebras por rollo | FN15: Perímetro | FQ15: Aprovechamiento | FR15: hebras por rollo | FT15: Transversal | FV15: =IF(FL11="SI",FJ8,0) -> 0 | FW15: Aprovechamiento | FX15: hebras por rollo | FZ15: N° hilera | GA15: N° plantas | GB15: Centrales | GC15: Largo (m) | GD15: Carpas | GE15: Aprovechamiento | GF15: hebras por rollo | GH15: Perímetro | GK15: Aprovechamiento | GL15: hebras por rollo | GN15: Transversal | GP15: =IF(GF11="SI",GD8,0) -> 0 | GQ15: Aprovechamiento | GR15: hebras por rollo
B16: =+IF(H11="SI",1,"") -> 1 | C16: =+E16/$H$9 -> 3.5 | D16: =ROUNDDOWN(E16/$C$13,0) -> 0 | E16: 7 | F16: =IF(D16=0,0,D16+1) -> 0 | G16: =IF(H16="","",1/(H16+0.01)) -> 0.0070417576 | H16: =IF(E16>0,ROUNDDOWN(('Diseño estructura &CP'!$AZ$5/E16),0),"") -> 142 | J16: Lado 1 | K16: =IF(H11="SI",MAX(E16:E224),0) -> 160 | L16: metros | M16: =IFERROR(1/(N16+0.01),0) -> 0.33222591 | N16: =IFERROR(IF(K16="",0,ROUNDDOWN(('Diseño estructura &CP'!$AZ$6/K16),0)),0) -> 3 | P16: T1 | Q16: =IF(H$11="SI",B$14,"") -> 106 | R16: =IF(Q16="","",Q16*$R$15) -> 424 | S16: =1/(T16+0.01) -> 0.99009901 | T16: =IFERROR(ROUNDDOWN(('Diseño estructura &CP'!$AZ$8/R16),0),0) -> 1 | V16: =+IF(AB11="SI",1,"") -> 1 | W16: =+Y16/$H$9 -> 75 | X16: =ROUNDDOWN(Y16/$C$13,0) -> 12 | Y16: 150 | Z16: =IF(X16=0,0,X16+1) -> 13 | AA16: =IF(AB16="","",1/(AB16+0.01)) -> 0.16638935 | AB16: =IF(Y16>0,ROUNDDOWN(('Diseño estructura &CP'!$AZ$5/Y16),0),"") -> 6 | AD16: Lado 1 | AE16: =IF(AB11="SI",MAX(Y16:Y224),0) -> 189 | AF16: metros | AG16: =IFERROR(1/(AH16+0.01),0) -> 0.49751244 | AH16: =IFERROR(IF(AE16="",0,ROUNDDOWN(('Diseño estructura &CP'!$AZ$6/AE16),0)),0) -> 2 | AJ16: T1 | AK16: =IF(AB$11="SI",V$14,"") -> 55 | AL16: =IF(AK16="","",AK16*$R$15) -> 220 | AM16: =1/(AN16+0.01) -> 0.49751244 | AN16: =IFERROR(ROUNDDOWN(('Diseño estructura &CP'!$AZ$8/AL16),0),0) -> 2 | AP16: =+IF(AV11="SI",1,"") -> 1 | AQ16: =+AS16/$H$9 -> 80.5 | AR16: =ROUNDDOWN(AS16/$C$13,0) -> 13 | AS16: 161 | AT16: =IF(AR16=0,0,AR16+1) -> 14 | AU16: =IF(AV16="","",1/(AV16+0.01)) -> 0.16638935 | AV16: =IF(AS16>0,ROUNDDOWN(('Diseño estructura &CP'!$AZ$5/AS16),0),"") -> 6 | AX16: Lado 1 | AY16: =IF(AV11="SI",MAX(AS16:AS224),0) -> 164 | AZ16: metros | BA16: =IFERROR(1/(BB16+0.01),0) -> 0.33222591 | BB16: =IFERROR(IF(AY16="",0,ROUNDDOWN(('Diseño estructura &CP'!$AZ$6/AY16),0)),0) -> 3 | BD16: T1 | BE16: =IF(AV$11="SI",AP$14,"") -> 76 | BF16: =IF(BE16="","",BE16*$R$15) -> 304 | BG16: =1/(BH16+0.01) -> 0.99009901 | BH16: =IFERROR(ROUNDDOWN(('Diseño estructura &CP'!$AZ$8/BF16),0),0) -> 1 | BJ16: =+IF(BP11="SI",1,"") -> 1 | BK16: =+BM16/$H$9 -> 99.75 | BL16: =ROUNDDOWN(BM16/$BK$13,0) -> 18 | BM16: 199.5 | BN16: =IF(BL16=0,0,BL16+1) -> 19 | BO16: =IF(BP16="","",1/(BP16+0.01)) -> 0.1996008 | BP16: =IF(BM16>0,ROUNDDOWN(('Diseño estructura &CP'!$AZ$5/BM16),0),"") -> 5 | BR16: Lado 1 | BS16: =IF(BP11="SI",MAX(BM16:BM224),0) -> 199.5 | BT16: metros | BU16: =IFERROR(1/(BV16+0.01),0) -> 0.49751244 | BV16: =IFERROR(IF(BS16="",0,ROUNDDOWN(('Diseño estructura &CP'!$AZ$6/BS16),0)),0) -> 2 | BX16: T1 | BY16: =IF(BP$11="SI",BJ$14,"") -> 30 | BZ16: =IF(BY16="","",BY16*$R$15) -> 120 | CA16: =1/(CB16+0.01) -> 0.24937656 | CB16: =IFERROR(ROUNDDOWN(('Diseño estructura &CP'!$AZ$8/BZ16),0),0) -> 4 | CD16: =+IF(CJ11="SI",1,"") | CE16: =+CG16/$H$9 -> 0 | CF16: =ROUNDDOWN(CG16/$C$13,0) -> 0 | CH16: =IF(CF16=0,0,CF16+1) -> 0 | CI16: =IF(CJ16="","",1/(CJ16+0.01)) | CJ16: =IF(CG16>0,ROUNDDOWN(('Diseño estructura &CP'!$AZ$5/CG16),0),"") | CL16: Lado 1 | CM16: =IF(CJ11="SI",MAX(CG16:CG224),0) -> 0 | CN16: metros | CO16: =IFERROR(1/(CP16+0.01),0) -> 100 | CP16: =IFERROR(IF(CM16="",0,ROUNDDOWN(('Diseño estructura &CP'!$AZ$6/CM16),0)),0) -> 0 | CR16: T1 | CS16: =IF(CJ$11="SI",CD$14,"") | CT16: =IF(CS16="","",CS16*$R$15) | CU16: =1/(CV16+0.01) -> 100 | CV16: =IFERROR(ROUNDDOWN(('Diseño estructura &CP'!$AZ$8/CT16),0),0) -> 0 | CX16: =+IF(DD11="SI",1,"") | CY16: =+DA16/$H$9 -> 0 | CZ16: =ROUNDDOWN(DA16/$C$13,0) -> 0 | DB16: =IF(CZ16=0,0,CZ16+1) -> 0 | DC16: =IF(DD16="","",1/(DD16+0.01)) | DD16: =IF(DA16>0,ROUNDDOWN(('Diseño estructura &CP'!$AZ$5/DA16),0),"") | DF16: Lado 1 | DG16: =IF(DD11="SI",MAX(DA16:DA224),0) -> 0 | DH16: metros | DI16: =IFERROR(1/(DJ16+0.01),0) -> 100 | DJ16: =IFERROR(IF(DG16="",0,ROUNDDOWN(('Diseño estructura &CP'!$AZ$6/DG16),0)),0) -> 0 | DL16: T1 | DM16: =IF(DD$11="SI",CX$14,"") | DN16: =IF(DM16="","",DM16*$R$15) | DO16: =1/(DP16+0.01) -> 100 | DP16: =IFERROR(ROUNDDOWN(('Diseño estructura &CP'!$AZ$8/DN16),0),0) -> 0 | DR16: =+IF(DX11="SI",1,"") | DS16: =+DU16/$H$9 -> 0 | DT16: =ROUNDDOWN(DU16/$C$13,0) -> 0 | DV16: =IF(DT16=0,0,DT16+1) -> 0 | DW16: =IF(DX16="","",1/(DX16+0.01)) | DX16: =IF(DU16>0,ROUNDDOWN(('Diseño estructura &CP'!$AZ$5/DU16),0),"") | DZ16: Lado 1 | EA16: =IF(DX11="SI",MAX(DU16:DU224),0) -> 0 | EB16: metros | EC16: =IFERROR(1/(ED16+0.01),0) -> 100 | ED16: =IFERROR(IF(EA16="",0,ROUNDDOWN(('Diseño estructura &CP'!$AZ$6/EA16),0)),0) -> 0 | EF16: T1 | EG16: =IF(DX$11="SI",DR$14,"") | EH16: =IF(EG16="","",EG16*$R$15) | EI16: =1/(EJ16+0.01) -> 100 | EJ16: =IFERROR(ROUNDDOWN(('Diseño estructura &CP'!$AZ$8/EH16),0),0) -> 0 | EL16: =+IF(ER11="SI",1,"") | EM16: =+EO16/$H$9 -> 0 | EN16: =ROUNDDOWN(EO16/$C$13,0) -> 0 | EP16: =IF(EN16=0,0,EN16+1) -> 0 | EQ16: =IF(ER16="","",1/(ER16+0.01)) | ER16: =IF(EO16>0,ROUNDDOWN(('Diseño estructura &CP'!$AZ$5/EO16),0),"") | ET16: Lado 1 | EU16: =IF(ER11="SI",MAX(EO16:EO224),0) -> 0 | EV16: metros | EW16: =IFERROR(1/(EX16+0.01),0) -> 100 | EX16: =IFERROR(IF(EU16="",0,ROUNDDOWN(('Diseño estructura &CP'!$AZ$6/EU16),0)),0) -> 0 | EZ16: T1 | FA16: =IF(ER$11="SI",EL$14,"") | FB16: =IF(FA16="","",FA16*$R$15) | FC16: =1/(FD16+0.01) -> 100 | FD16: =IFERROR(ROUNDDOWN(('Diseño estructura &CP'!$AZ$8/FB16),0),0) -> 0 | FF16: =+IF(FL11="SI",1,"") | FG16: =+FI16/$H$9 -> 0 | FH16: =ROUNDDOWN(FI16/$C$13,0) -> 0 | FJ16: =IF(FH16=0,0,FH16+1) -> 0 | FK16: =IF(FL16="","",1/(FL16+0.01)) | FL16: =IF(FI16>0,ROUNDDOWN(('Diseño estructura &CP'!$AZ$5/FI16),0),"") | FN16: Lado 1 | FO16: =IF(FL11="SI",MAX(FI16:FI224),0) -> 0 | FP16: metros | FQ16: =IFERROR(1/(FR16+0.01),0) -> 100 | FR16: =IFERROR(IF(FO16="",0,ROUNDDOWN(('Diseño estructura &CP'!$AZ$6/FO16),0)),0) -> 0 | FT16: T1 | FU16: =IF(FL$11="SI",FF$14,"") | FV16: =IF(FU16="","",FU16*$R$15) | FW16: =1/(FX16+0.01) -> 100 | FX16: =IFERROR(ROUNDDOWN(('Diseño estructura &CP'!$AZ$8/FV16),0),0) -> 0 | FZ16: =+IF(GF11="SI",1,"") | GA16: =+GC16/$H$9 -> 0 | GB16: =ROUNDDOWN(GC16/$C$13,0) -> 0 | GD16: =IF(GB16=0,0,GB16+1) -> 0 | GE16: =IF(GF16="","",1/(GF16+0.01)) | GF16: =IF(GC16>0,ROUNDDOWN(('Diseño estructura &CP'!$AZ$5/GC16),0),"") | GH16: Lado 1 | GI16: =IF(GF11="SI",MAX(GC16:GC224),0) -> 0 | GJ16: metros | GK16: =IFERROR(1/(GL16+0.01),0) -> 100 | GL16: =IFERROR(IF(GI16="",0,ROUNDDOWN(('Diseño estructura &CP'!$AZ$6/GI16),0)),0) -> 0 | GN16: T1 | GO16: =IF(GF$11="SI",FZ$14,"") | GP16: =IF(GO16="","",GO16*$R$15) | GQ16: =1/(GR16+0.01) -> 100 | GR16: =IFERROR(ROUNDDOWN(('Diseño estructura &CP'!$AZ$8/GP16),0),0) -> 0
B17: =+IF(C17=0,"",B16+1) -> 2 | C17: =+E17/$H$9 -> 6 | D17: =ROUNDDOWN(E17/$C$13,0) -> 1 | E17: 12 | F17: =IF(D17=0,0,D17+1) -> 2 | G17: =IF(H17="","",1/(H17+0.01)) -> 0.012046741 | H17: =IF(E17>0,ROUNDDOWN(('Diseño estructura &CP'!$AZ$5/E17),0),"") -> 83 | J17: Lado 2 | K17: =IF(H11="SI",MAX(E16:E224),0) -> 160 | L17: metros | M17: =IFERROR(1/(N17+0.01),0) -> 0.33222591 | N17: =IFERROR(IF(K17="",0,ROUNDDOWN(('Diseño estructura &CP'!$AZ$6/K17),0)),0) -> 3 | P17: T2 | Q17: =IF(H$11="SI",B$14,"") -> 106 | R17: =IF(Q17="","",Q17*$R$15) -> 424 | S17: =1/(T17+0.01) -> 0.99009901 | T17: =IFERROR(ROUNDDOWN(('Diseño estructura &CP'!$AZ$8/R17),0),0) -> 1 | V17: =+IF(W17=0,"",V16+1) -> 2 | W17: =+Y17/$H$9 -> 76 | X17: =ROUNDDOWN(Y17/$C$13,0) -> 12 | Y17: 152 | Z17: =IF(X17=0,0,X17+1) -> 13 | AA17: =IF(AB17="","",1/(AB17+0.01)) -> 0.16638935 | AB17: =IF(Y17>0,ROUNDDOWN(('Diseño estructura &CP'!$AZ$5/Y17),0),"") -> 6 | AD17: Lado 2 | AE17: =IF(AB11="SI",MAX(Y16:Y224),0) -> 189 | AF17: metros | AG17: =IFERROR(1/(AH17+0.01),0) -> 0.49751244 | AH17: =IFERROR(IF(AE17="",0,ROUNDDOWN(('Diseño estructura &CP'!$AZ$6/AE17),0)),0) -> 2 | AJ17: T2 | AK17: =IF(AB$11="SI",V$14,"") -> 55 | AL17: =IF(AK17="","",AK17*$R$15) -> 220 | AM17: =1/(AN17+0.01) -> 0.49751244 | AN17: =IFERROR(ROUNDDOWN(('Diseño estructura &CP'!$AZ$8/AL17),0),0) -> 2 | AP17: =+IF(AQ17=0,"",AP16+1) -> 2 | AQ17: =+AS17/$H$9 -> 81 | AR17: =ROUNDDOWN(AS17/$C$13,0) -> 13 | AS17: 162 | AT17: =IF(AR17=0,0,AR17+1) -> 14 | AU17: =IF(AV17="","",1/(AV17+0.01)) -> 0.16638935 | AV17: =IF(AS17>0,ROUNDDOWN(('Diseño estructura &CP'!$AZ$5/AS17),0),"") -> 6 | AX17: Lado 2 | AY17: 330 | AZ17: metros | BA17: =IFERROR(1/(BB17+0.01),0) -> 0.99009901 | BB17: =IFERROR(IF(AY17="",0,ROUNDDOWN(('Diseño estructura &CP'!$AZ$6/AY17),0)),0) -> 1 | BD17: T2 | BE17: =IF(AV$11="SI",AP$14,"") -> 76 | BF17: =IF(BE17="","",BE17*$R$15) -> 304 | BG17: =1/(BH17+0.01) -> 0.99009901 | BH17: =IFERROR(ROUNDDOWN(('Diseño estructura &CP'!$AZ$8/BF17),0),0) -> 1 | BJ17: =+IF(BK17=0,"",BJ16+1) -> 2 | BK17: =+BM17/$H$9 -> 99.5 | BL17: =ROUNDDOWN(BM17/$BK$13,0) -> 18 | BM17: 199 | BN17: =IF(BL17=0,0,BL17+1) -> 19 | BO17: =IF(BP17="","",1/(BP17+0.01)) -> 0.1996008 | BP17: =IF(BM17>0,ROUNDDOWN(('Diseño estructura &CP'!$AZ$5/BM17),0),"") -> 5 | BR17: Lado 2 | BS17: 340 | BT17: metros | BU17: =IFERROR(1/(BV17+0.01),0) -> 0.99009901 | BV17: =IFERROR(IF(BS17="",0,ROUNDDOWN(('Diseño estructura &CP'!$AZ$6/BS17),0)),0) -> 1 | BX17: T2 | BY17: =IF(BP$11="SI",BJ$14,"") -> 30 | BZ17: =IF(BY17="","",BY17*$R$15) -> 120 | CA17: =1/(CB17+0.01) -> 0.24937656 | CB17: =IFERROR(ROUNDDOWN(('Diseño estructura &CP'!$AZ$8/BZ17),0),0) -> 4 | CD17: =+IF(CE17=0,"",CD16+1) | CE17: =+CG17/$H$9 -> 0 | CF17: =ROUNDDOWN(CG17/$C$13,0) -> 0 | CH17: =IF(CF17=0,0,CF17+1) -> 0 | CI17: =IF(CJ17="","",1/(CJ17+0.01)) | CJ17: =IF(CG17>0,ROUNDDOWN(('Diseño estructura &CP'!$AZ$5/CG17),0),"") | CL17: Lado 2 | CM17: =IF(CJ11="SI",MAX(CG16:CG224),0) -> 0 | CN17: metros | CO17: =IFERROR(1/(CP17+0.01),0) -> 100 | CP17: =IFERROR(IF(CM17="",0,ROUNDDOWN(('Diseño estructura &CP'!$AZ$6/CM17),0)),0) -> 0 | CR17: T2 | CS17: =IF(CJ$11="SI",CD$14,"") | CT17: =IF(CS17="","",CS17*$R$15) | CU17: =1/(CV17+0.01) -> 100 | CV17: =IFERROR(ROUNDDOWN(('Diseño estructura &CP'!$AZ$8/CT17),0),0) -> 0 | CX17: =+IF(CY17=0,"",CX16+1) | CY17: =+DA17/$H$9 -> 0 | CZ17: =ROUNDDOWN(DA17/$C$13,0) -> 0 | DB17: =IF(CZ17=0,0,CZ17+1) -> 0 | DC17: =IF(DD17="","",1/(DD17+0.01)) | DD17: =IF(DA17>0,ROUNDDOWN(('Diseño estructura &CP'!$AZ$5/DA17),0),"") | DF17: Lado 2 | DG17: =IF(DD11="SI",MAX(DA16:DA224),0) -> 0 | DH17: metros | DI17: =IFERROR(1/(DJ17+0.01),0) -> 100 | DJ17: =IFERROR(IF(DG17="",0,ROUNDDOWN(('Diseño estructura &CP'!$AZ$6/DG17),0)),0) -> 0 | DL17: T2 | DM17: =IF(DD$11="SI",CX$14,"") | DN17: =IF(DM17="","",DM17*$R$15) | DO17: =1/(DP17+0.01) -> 100 | DP17: =IFERROR(ROUNDDOWN(('Diseño estructura &CP'!$AZ$8/DN17),0),0) -> 0 | DR17: =+IF(DS17=0,"",DR16+1) | DS17: =+DU17/$H$9 -> 0 | DT17: =ROUNDDOWN(DU17/$C$13,0) -> 0 | DV17: =IF(DT17=0,0,DT17+1) -> 0 | DW17: =IF(DX17="","",1/(DX17+0.01)) | DX17: =IF(DU17>0,ROUNDDOWN(('Diseño estructura &CP'!$AZ$5/DU17),0),"") | DZ17: Lado 2 | EA17: =IF(DX11="SI",MAX(DU16:DU224),0) -> 0 | EB17: metros | EC17: =IFERROR(1/(ED17+0.01),0) -> 100 | ED17: =IFERROR(IF(EA17="",0,ROUNDDOWN(('Diseño estructura &CP'!$AZ$6/EA17),0)),0) -> 0 | EF17: T2 | EG17: =IF(DX$11="SI",DR$14,"") | EH17: =IF(EG17="","",EG17*$R$15) | EI17: =1/(EJ17+0.01) -> 100 | EJ17: =IFERROR(ROUNDDOWN(('Diseño estructura &CP'!$AZ$8/EH17),0),0) -> 0 | EL17: =+IF(EM17=0,"",EL16+1) | EM17: =+EO17/$H$9 -> 0 | EN17: =ROUNDDOWN(EO17/$C$13,0) -> 0 | EP17: =IF(EN17=0,0,EN17+1) -> 0 | EQ17: =IF(ER17="","",1/(ER17+0.01)) | ER17: =IF(EO17>0,ROUNDDOWN(('Diseño estructura &CP'!$AZ$5/EO17),0),"") | ET17: Lado 2 | EU17: =IF(ER11="SI",MAX(EO16:EO224),0) -> 0 | EV17: metros | EW17: =IFERROR(1/(EX17+0.01),0) -> 100 | EX17: =IFERROR(IF(EU17="",0,ROUNDDOWN(('Diseño estructura &CP'!$AZ$6/EU17),0)),0) -> 0 | EZ17: T2 | FA17: =IF(ER$11="SI",EL$14,"") | FB17: =IF(FA17="","",FA17*$R$15) | FC17: =1/(FD17+0.01) -> 100 | FD17: =IFERROR(ROUNDDOWN(('Diseño estructura &CP'!$AZ$8/FB17),0),0) -> 0 | FF17: =+IF(FG17=0,"",FF16+1) | FG17: =+FI17/$H$9 -> 0 | FH17: =ROUNDDOWN(FI17/$C$13,0) -> 0 | FJ17: =IF(FH17=0,0,FH17+1) -> 0 | FK17: =IF(FL17="","",1/(FL17+0.01)) | FL17: =IF(FI17>0,ROUNDDOWN(('Diseño estructura &CP'!$AZ$5/FI17),0),"") | FN17: Lado 2 | FO17: =IF(FL11="SI",MAX(FI16:FI224),0) -> 0 | FP17: metros | FQ17: =IFERROR(1/(FR17+0.01),0) -> 100 | FR17: =IFERROR(IF(FO17="",0,ROUNDDOWN(('Diseño estructura &CP'!$AZ$6/FO17),0)),0) -> 0 | FT17: T2 | FU17: =IF(FL$11="SI",FF$14,"") | FV17: =IF(FU17="","",FU17*$R$15) | FW17: =1/(FX17+0.01) -> 100 | FX17: =IFERROR(ROUNDDOWN(('Diseño estructura &CP'!$AZ$8/FV17),0),0) -> 0 | FZ17: =+IF(GA17=0,"",FZ16+1) | GA17: =+GC17/$H$9 -> 0 | GB17: =ROUNDDOWN(GC17/$C$13,0) -> 0 | GD17: =IF(GB17=0,0,GB17+1) -> 0 | GE17: =IF(GF17="","",1/(GF17+0.01)) | GF17: =IF(GC17>0,ROUNDDOWN(('Diseño estructura &CP'!$AZ$5/GC17),0),"") | GH17: Lado 2 | GI17: =IF(GF11="SI",MAX(GC16:GC224),0) -> 0 | GJ17: metros | GK17: =IFERROR(1/(GL17+0.01),0) -> 100 | GL17: =IFERROR(IF(GI17="",0,ROUNDDOWN(('Diseño estructura &CP'!$AZ$6/GI17),0)),0) -> 0 | GN17: T2 | GO17: =IF(GF$11="SI",FZ$14,"") | GP17: =IF(GO17="","",GO17*$R$15) | GQ17: =1/(GR17+0.01) -> 100 | GR17: =IFERROR(ROUNDDOWN(('Diseño estructura &CP'!$AZ$8/GP17),0),0) -> 0
B18: =+IF(C18=0,"",B17+1) -> 3 | C18: =+E18/$H$9 -> 7.5 | D18: =ROUNDDOWN(E18/$C$13,0) -> 1 | E18: 15 | F18: =IF(D18=0,0,D18+1) -> 2 | G18: =IF(H18="","",1/(H18+0.01)) -> 0.01514922 | H18: =IF(E18>0,ROUNDDOWN(('Diseño estructura &CP'!$AZ$5/E18),0),"") -> 66 | J18: Lado 3 | K18: =IF(H11="SI",B14*F8,0) -> 424 | L18: metros | M18: =IFERROR(1/(N18+0.01),0) -> 0.99009901 | N18: =IFERROR(IF(K18="",0,ROUNDDOWN(('Diseño estructura &CP'!$AZ$6/K18),0)),0) -> 1 | P18: T3 | Q18: =IF(H$11="SI",B$14,"") -> 106 | R18: =IF(Q18="","",Q18*$R$15) -> 424 | S18: =1/(T18+0.01) -> 0.99009901 | T18: =IFERROR(ROUNDDOWN(('Diseño estructura &CP'!$AZ$8/R18),0),0) -> 1 | V18: =+IF(W18=0,"",V17+1) -> 3 | W18: =+Y18/$H$9 -> 76.5 | X18: =ROUNDDOWN(Y18/$C$13,0) -> 12 | Y18: 153 | Z18: =IF(X18=0,0,X18+1) -> 13 | AA18: =IF(AB18="","",1/(AB18+0.01)) -> 0.16638935 | AB18: =IF(Y18>0,ROUNDDOWN(('Diseño estructura &CP'!$AZ$5/Y18),0),"") -> 6 | AD18: Lado 3 | AE18: =IF(AB11="SI",V14*Z8,0) -> 220 | AF18: metros | AG18: =IFERROR(1/(AH18+0.01),0) -> 0.49751244 | AH18: =IFERROR(IF(AE18="",0,ROUNDDOWN(('Diseño estructura &CP'!$AZ$6/AE18),0)),0) -> 2 | AJ18: T3 | AK18: =IF(AB$11="SI",V$14,"") -> 55 | AL18: =IF(AK18="","",AK18*$R$15) -> 220 | AM18: =1/(AN18+0.01) -> 0.49751244 | AN18: =IFERROR(ROUNDDOWN(('Diseño estructura &CP'!$AZ$8/AL18),0),0) -> 2 | AP18: =+IF(AQ18=0,"",AP17+1) -> 3 | AQ18: =+AS18/$H$9 -> 81 | AR18: =ROUNDDOWN(AS18/$C$13,0) -> 13 | AS18: 162 | AT18: =IF(AR18=0,0,AR18+1) -> 14 | AU18: =IF(AV18="","",1/(AV18+0.01)) -> 0.16638935 | AV18: =IF(AS18>0,ROUNDDOWN(('Diseño estructura &CP'!$AZ$5/AS18),0),"") -> 6 | AX18: Lado 3 | AY18: =IF(AV11="SI",AP14*AT8,0) -> 304 | AZ18: metros | BA18: =IFERROR(1/(BB18+0.01),0) -> 0.99009901 | BB18: =IFERROR(IF(AY18="",0,ROUNDDOWN(('Diseño estructura &CP'!$AZ$6/AY18),0)),0) -> 1 | BD18: T3 | BE18: =IF(AV$11="SI",AP$14,"") -> 76 | BF18: =IF(BE18="","",BE18*$R$15) -> 304 | BG18: =1/(BH18+0.01) -> 0.99009901 | BH18: =IFERROR(ROUNDDOWN(('Diseño estructura &CP'!$AZ$8/BF18),0),0) -> 1 | BJ18: =+IF(BK18=0,"",BJ17+1) -> 3 | BK18: =+BM18/$H$9 -> 99.25 | BL18: =ROUNDDOWN(BM18/$BK$13,0) -> 18 | BM18: 198.5 | BN18: =IF(BL18=0,0,BL18+1) -> 19 | BO18: =IF(BP18="","",1/(BP18+0.01)) -> 0.1996008 | BP18: =IF(BM18>0,ROUNDDOWN(('Diseño estructura &CP'!$AZ$5/BM18),0),"") -> 5 | BR18: Lado 3 | BS18: =IF(BP11="SI",BJ14*BN8,0) -> 135 | BT18: metros | BU18: =IFERROR(1/(BV18+0.01),0) -> 0.33222591 | BV18: =IFERROR(IF(BS18="",0,ROUNDDOWN(('Diseño estructura &CP'!$AZ$6/BS18),0)),0) -> 3 | BX18: T3 | BY18: =IF(BP$11="SI",BJ$14,"") -> 30 | BZ18: =IF(BY18="","",BY18*$R$15) -> 120 | CA18: =1/(CB18+0.01) -> 0.24937656 | CB18: =IFERROR(ROUNDDOWN(('Diseño estructura &CP'!$AZ$8/BZ18),0),0) -> 4 | CD18: =+IF(CE18=0,"",CD17+1) | CE18: =+CG18/$H$9 -> 0 | CF18: =ROUNDDOWN(CG18/$C$13,0) -> 0 | CH18: =IF(CF18=0,0,CF18+1) -> 0 | CI18: =IF(CJ18="","",1/(CJ18+0.01)) | CJ18: =IF(CG18>0,ROUNDDOWN(('Diseño estructura &CP'!$AZ$5/CG18),0),"") | CL18: Lado 3 | CM18: =IF(CJ11="SI",CD14*CH8,0) -> 0 | CN18: metros | CO18: =IFERROR(1/(CP18+0.01),0) -> 100 | CP18: =IFERROR(IF(CM18="",0,ROUNDDOWN(('Diseño estructura &CP'!$AZ$6/CM18),0)),0) -> 0 | CR18: T3 | CS18: =IF(CJ$11="SI",CD$14,"") | CT18: =IF(CS18="","",CS18*$R$15) | CU18: =1/(CV18+0.01) -> 100 | CV18: =IFERROR(ROUNDDOWN(('Diseño estructura &CP'!$AZ$8/CT18),0),0) -> 0 | CX18: =+IF(CY18=0,"",CX17+1) | CY18: =+DA18/$H$9 -> 0 | CZ18: =ROUNDDOWN(DA18/$C$13,0) -> 0 | DB18: =IF(CZ18=0,0,CZ18+1) -> 0 | DC18: =IF(DD18="","",1/(DD18+0.01)) | DD18: =IF(DA18>0,ROUNDDOWN(('Diseño estructura &CP'!$AZ$5/DA18),0),"") | DF18: Lado 3 | DG18: =IF(DD11="SI",CX14*DB8,0) -> 0 | DH18: metros | DI18: =IFERROR(1/(DJ18+0.01),0) -> 100 | DJ18: =IFERROR(IF(DG18="",0,ROUNDDOWN(('Diseño estructura &CP'!$AZ$6/DG18),0)),0) -> 0 | DL18: T3 | DM18: =IF(DD$11="SI",CX$14,"") | DN18: =IF(DM18="","",DM18*$R$15) | DO18: =1/(DP18+0.01) -> 100 | DP18: =IFERROR(ROUNDDOWN(('Diseño estructura &CP'!$AZ$8/DN18),0),0) -> 0 | DR18: =+IF(DS18=0,"",DR17+1) | DS18: =+DU18/$H$9 -> 0 | DT18: =ROUNDDOWN(DU18/$C$13,0) -> 0 | DV18: =IF(DT18=0,0,DT18+1) -> 0 | DW18: =IF(DX18="","",1/(DX18+0.01)) | DX18: =IF(DU18>0,ROUNDDOWN(('Diseño estructura &CP'!$AZ$5/DU18),0),"") | DZ18: Lado 3 | EA18: =IF(DX11="SI",DR14*DV8,0) -> 0 | EB18: metros | EC18: =IFERROR(1/(ED18+0.01),0) -> 100 | ED18: =IFERROR(IF(EA18="",0,ROUNDDOWN(('Diseño estructura &CP'!$AZ$6/EA18),0)),0) -> 0 | EF18: T3 | EG18: =IF(DX$11="SI",DR$14,"") | EH18: =IF(EG18="","",EG18*$R$15) | EI18: =1/(EJ18+0.01) -> 100 | EJ18: =IFERROR(ROUNDDOWN(('Diseño estructura &CP'!$AZ$8/EH18),0),0) -> 0 | EL18: =+IF(EM18=0,"",EL17+1) | EM18: =+EO18/$H$9 -> 0 | EN18: =ROUNDDOWN(EO18/$C$13,0) -> 0 | EP18: =IF(EN18=0,0,EN18+1) -> 0 | EQ18: =IF(ER18="","",1/(ER18+0.01)) | ER18: =IF(EO18>0,ROUNDDOWN(('Diseño estructura &CP'!$AZ$5/EO18),0),"") | ET18: Lado 3 | EU18: =IF(ER11="SI",EL14*EP8,0) -> 0 | EV18: metros | EW18: =IFERROR(1/(EX18+0.01),0) -> 100 | EX18: =IFERROR(IF(EU18="",0,ROUNDDOWN(('Diseño estructura &CP'!$AZ$6/EU18),0)),0) -> 0 | EZ18: T3 | FA18: =IF(ER$11="SI",EL$14,"") | FB18: =IF(FA18="","",FA18*$R$15) | FC18: =1/(FD18+0.01) -> 100 | FD18: =IFERROR(ROUNDDOWN(('Diseño estructura &CP'!$AZ$8/FB18),0),0) -> 0 | FF18: =+IF(FG18=0,"",FF17+1) | FG18: =+FI18/$H$9 -> 0 | FH18: =ROUNDDOWN(FI18/$C$13,0) -> 0 | FJ18: =IF(FH18=0,0,FH18+1) -> 0 | FK18: =IF(FL18="","",1/(FL18+0.01)) | FL18: =IF(FI18>0,ROUNDDOWN(('Diseño estructura &CP'!$AZ$5/FI18),0),"") | FN18: Lado 3 | FO18: =IF(FL11="SI",FF14*FJ8,0) -> 0 | FP18: metros | FQ18: =IFERROR(1/(FR18+0.01),0) -> 100 | FR18: =IFERROR(IF(FO18="",0,ROUNDDOWN(('Diseño estructura &CP'!$AZ$6/FO18),0)),0) -> 0 | FT18: T3 | FU18: =IF(FL$11="SI",FF$14,"") | FV18: =IF(FU18="","",FU18*$R$15) | FW18: =1/(FX18+0.01) -> 100 | FX18: =IFERROR(ROUNDDOWN(('Diseño estructura &CP'!$AZ$8/FV18),0),0) -> 0 | FZ18: =+IF(GA18=0,"",FZ17+1) | GA18: =+GC18/$H$9 -> 0 | GB18: =ROUNDDOWN(GC18/$C$13,0) -> 0 | GD18: =IF(GB18=0,0,GB18+1) -> 0 | GE18: =IF(GF18="","",1/(GF18+0.01)) | GF18: =IF(GC18>0,ROUNDDOWN(('Diseño estructura &CP'!$AZ$5/GC18),0),"") | GH18: Lado 3 | GI18: =IF(GF11="SI",FZ14*GD8,0) -> 0 | GJ18: metros | GK18: =IFERROR(1/(GL18+0.01),0) -> 100 | GL18: =IFERROR(IF(GI18="",0,ROUNDDOWN(('Diseño estructura &CP'!$AZ$6/GI18),0)),0) -> 0 | GN18: T3 | GO18: =IF(GF$11="SI",FZ$14,"") | GP18: =IF(GO18="","",GO18*$R$15) | GQ18: =1/(GR18+0.01) -> 100 | GR18: =IFERROR(ROUNDDOWN(('Diseño estructura &CP'!$AZ$8/GP18),0),0) -> 0
B19: =+IF(C19=0,"",B18+1) -> 4 | C19: =+E19/$H$9 -> 9.5 | D19: =ROUNDDOWN(E19/$C$13,0) -> 1 | E19: 19 | F19: =IF(D19=0,0,D19+1) -> 2 | G19: =IF(H19="","",1/(H19+0.01)) -> 0.019227072 | H19: =IF(E19>0,ROUNDDOWN(('Diseño estructura &CP'!$AZ$5/E19),0),"") -> 52 | J19: Lado 4 | K19: =IF(H11="SI",B14*F8,0) -> 424 | L19: metros | M19: =IFERROR(1/(N19+0.01),0) -> 0.99009901 | N19: =IFERROR(IF(K19="",0,ROUNDDOWN(('Diseño estructura &CP'!$AZ$6/K19),0)),0) -> 1 | P19: T4 | Q19: =IF(H$11="SI",B$14,"") -> 106 | R19: =IF(Q19="","",Q19*$R$15) -> 424 | S19: =1/(T19+0.01) -> 0.99009901 | T19: =IFERROR(ROUNDDOWN(('Diseño estructura &CP'!$AZ$8/R19),0),0) -> 1 | V19: =+IF(W19=0,"",V18+1) -> 4 | W19: =+Y19/$H$9 -> 77.75 | X19: =ROUNDDOWN(Y19/$C$13,0) -> 12 | Y19: 155.5 | Z19: =IF(X19=0,0,X19+1) -> 13 | AA19: =IF(AB19="","",1/(AB19+0.01)) -> 0.16638935 | AB19: =IF(Y19>0,ROUNDDOWN(('Diseño estructura &CP'!$AZ$5/Y19),0),"") -> 6 | AD19: Lado 4 | AE19: =IF(AB11="SI",V14*Z8,0) -> 220 | AF19: metros | AG19: =IFERROR(1/(AH19+0.01),0) -> 0.49751244 | AH19: =IFERROR(IF(AE19="",0,ROUNDDOWN(('Diseño estructura &CP'!$AZ$6/AE19),0)),0) -> 2 | AJ19: T4 | AK19: =IF(AB$11="SI",V$14,"") -> 55 | AL19: =IF(AK19="","",AK19*$R$15) -> 220 | AM19: =1/(AN19+0.01) -> 0.49751244 | AN19: =IFERROR(ROUNDDOWN(('Diseño estructura &CP'!$AZ$8/AL19),0),0) -> 2 | AP19: =+IF(AQ19=0,"",AP18+1) -> 4 | AQ19: =+AS19/$H$9 -> 81.5 | AR19: =ROUNDDOWN(AS19/$C$13,0) -> 13 | AS19: 163 | AT19: =IF(AR19=0,0,AR19+1) -> 14 | AU19: =IF(AV19="","",1/(AV19+0.01)) -> 0.16638935 | AV19: =IF(AS19>0,ROUNDDOWN(('Diseño estructura &CP'!$AZ$5/AS19),0),"") -> 6 | AX19: Lado 4 | AY19: =IF(AV11="SI",AP14*AT8,0) -> 304 | AZ19: metros | BA19: =IFERROR(1/(BB19+0.01),0) -> 0.99009901 | BB19: =IFERROR(IF(AY19="",0,ROUNDDOWN(('Diseño estructura &CP'!$AZ$6/AY19),0)),0) -> 1 | BD19: T4 | BE19: =IF(AV$11="SI",AP$14,"") -> 76 | BF19: =IF(BE19="","",BE19*$R$15) -> 304 | BG19: =1/(BH19+0.01) -> 0.99009901 | BH19: =IFERROR(ROUNDDOWN(('Diseño estructura &CP'!$AZ$8/BF19),0),0) -> 1 | BJ19: =+IF(BK19=0,"",BJ18+1) -> 4 | BK19: =+BM19/$H$9 -> 98.75 | BL19: =ROUNDDOWN(BM19/$BK$13,0) -> 17 | BM19: 197.5 | BN19: =IF(BL19=0,0,BL19+1) -> 18 | BO19: =IF(BP19="","",1/(BP19+0.01)) -> 0.1996008 | BP19: =IF(BM19>0,ROUNDDOWN(('Diseño estructura &CP'!$AZ$5/BM19),0),"") -> 5 | BR19: Lado 4 | BS19: =IF(BP11="SI",BJ14*BN8,0) -> 135 | BT19: metros | BU19: =IFERROR(1/(BV19+0.01),0) -> 0.33222591 | BV19: =IFERROR(IF(BS19="",0,ROUNDDOWN(('Diseño estructura &CP'!$AZ$6/BS19),0)),0) -> 3 | BX19: T4 | BY19: =IF(BP$11="SI",BJ$14,"") -> 30 | BZ19: =IF(BY19="","",BY19*$R$15) -> 120 | CA19: =1/(CB19+0.01) -> 0.24937656 | CB19: =IFERROR(ROUNDDOWN(('Diseño estructura &CP'!$AZ$8/BZ19),0),0) -> 4 | CD19: =+IF(CE19=0,"",CD18+1) | CE19: =+CG19/$H$9 -> 0 | CF19: =ROUNDDOWN(CG19/$C$13,0) -> 0 | CH19: =IF(CF19=0,0,CF19+1) -> 0 | CI19: =IF(CJ19="","",1/(CJ19+0.01)) | CJ19: =IF(CG19>0,ROUNDDOWN(('Diseño estructura &CP'!$AZ$5/CG19),0),"") | CL19: Lado 4 | CM19: =IF(CJ11="SI",CD14*CH8,0) -> 0 | CN19: metros | CO19: =IFERROR(1/(CP19+0.01),0) -> 100 | CP19: =IFERROR(IF(CM19="",0,ROUNDDOWN(('Diseño estructura &CP'!$AZ$6/CM19),0)),0) -> 0 | CR19: T4 | CS19: =IF(CJ$11="SI",CD$14,"") | CT19: =IF(CS19="","",CS19*$R$15) | CU19: =1/(CV19+0.01) -> 100 | CV19: =IFERROR(ROUNDDOWN(('Diseño estructura &CP'!$AZ$8/CT19),0),0) -> 0 | CX19: =+IF(CY19=0,"",CX18+1) | CY19: =+DA19/$H$9 -> 0 | CZ19: =ROUNDDOWN(DA19/$C$13,0) -> 0 | DB19: =IF(CZ19=0,0,CZ19+1) -> 0 | DC19: =IF(DD19="","",1/(DD19+0.01)) | DD19: =IF(DA19>0,ROUNDDOWN(('Diseño estructura &CP'!$AZ$5/DA19),0),"") | DF19: Lado 4 | DG19: =IF(DD11="SI",CX14*DB8,0) -> 0 | DH19: metros | DI19: =IFERROR(1/(DJ19+0.01),0) -> 100 | DJ19: =IFERROR(IF(DG19="",0,ROUNDDOWN(('Diseño estructura &CP'!$AZ$6/DG19),0)),0) -> 0 | DL19: T4 | DM19: =IF(DD$11="SI",CX$14,"") | DN19: =IF(DM19="","",DM19*$R$15) | DO19: =1/(DP19+0.01) -> 100 | DP19: =IFERROR(ROUNDDOWN(('Diseño estructura &CP'!$AZ$8/DN19),0),0) -> 0 | DR19: =+IF(DS19=0,"",DR18+1) | DS19: =+DU19/$H$9 -> 0 | DT19: =ROUNDDOWN(DU19/$C$13,0) -> 0 | DV19: =IF(DT19=0,0,DT19+1) -> 0 | DW19: =IF(DX19="","",1/(DX19+0.01)) | DX19: =IF(DU19>0,ROUNDDOWN(('Diseño estructura &CP'!$AZ$5/DU19),0),"") | DZ19: Lado 4 | EA19: =IF(DX11="SI",DR14*DV8,0) -> 0 | EB19: metros | EC19: =IFERROR(1/(ED19+0.01),0) -> 100 | ED19: =IFERROR(IF(EA19="",0,ROUNDDOWN(('Diseño estructura &CP'!$AZ$6/EA19),0)),0) -> 0 | EF19: T4 | EG19: =IF(DX$11="SI",DR$14,"") | EH19: =IF(EG19="","",EG19*$R$15) | EI19: =1/(EJ19+0.01) -> 100 | EJ19: =IFERROR(ROUNDDOWN(('Diseño estructura &CP'!$AZ$8/EH19),0),0) -> 0 | EL19: =+IF(EM19=0,"",EL18+1) | EM19: =+EO19/$H$9 -> 0 | EN19: =ROUNDDOWN(EO19/$C$13,0) -> 0 | EP19: =IF(EN19=0,0,EN19+1) -> 0 | EQ19: =IF(ER19="","",1/(ER19+0.01)) | ER19: =IF(EO19>0,ROUNDDOWN(('Diseño estructura &CP'!$AZ$5/EO19),0),"") | ET19: Lado 4 | EU19: =IF(ER11="SI",EL14*EP8,0) -> 0 | EV19: metros | EW19: =IFERROR(1/(EX19+0.01),0) -> 100 | EX19: =IFERROR(IF(EU19="",0,ROUNDDOWN(('Diseño estructura &CP'!$AZ$6/EU19),0)),0) -> 0 | EZ19: T4 | FA19: =IF(ER$11="SI",EL$14,"") | FB19: =IF(FA19="","",FA19*$R$15) | FC19: =1/(FD19+0.01) -> 100 | FD19: =IFERROR(ROUNDDOWN(('Diseño estructura &CP'!$AZ$8/FB19),0),0) -> 0 | FF19: =+IF(FG19=0,"",FF18+1) | FG19: =+FI19/$H$9 -> 0 | FH19: =ROUNDDOWN(FI19/$C$13,0) -> 0 | FJ19: =IF(FH19=0,0,FH19+1) -> 0 | FK19: =IF(FL19="","",1/(FL19+0.01)) | FL19: =IF(FI19>0,ROUNDDOWN(('Diseño estructura &CP'!$AZ$5/FI19),0),"") | FN19: Lado 4 | FO19: =IF(FL11="SI",FF14*FJ8,0) -> 0 | FP19: metros | FQ19: =IFERROR(1/(FR19+0.01),0) -> 100 | FR19: =IFERROR(IF(FO19="",0,ROUNDDOWN(('Diseño estructura &CP'!$AZ$6/FO19),0)),0) -> 0 | FT19: T4 | FU19: =IF(FL$11="SI",FF$14,"") | FV19: =IF(FU19="","",FU19*$R$15) | FW19: =1/(FX19+0.01) -> 100 | FX19: =IFERROR(ROUNDDOWN(('Diseño estructura &CP'!$AZ$8/FV19),0),0) -> 0 | FZ19: =+IF(GA19=0,"",FZ18+1) | GA19: =+GC19/$H$9 -> 0 | GB19: =ROUNDDOWN(GC19/$C$13,0) -> 0 | GD19: =IF(GB19=0,0,GB19+1) -> 0 | GE19: =IF(GF19="","",1/(GF19+0.01)) | GF19: =IF(GC19>0,ROUNDDOWN(('Diseño estructura &CP'!$AZ$5/GC19),0),"") | GH19: Lado 4 | GI19: =IF(GF11="SI",FZ14*GD8,0) -> 0 | GJ19: metros | GK19: =IFERROR(1/(GL19+0.01),0) -> 100 | GL19: =IFERROR(IF(GI19="",0,ROUNDDOWN(('Diseño estructura &CP'!$AZ$6/GI19),0)),0) -> 0 | GN19: T4 | GO19: =IF(GF$11="SI",FZ$14,"") | GP19: =IF(GO19="","",GO19*$R$15) | GQ19: =1/(GR19+0.01) -> 100 | GR19: =IFERROR(ROUNDDOWN(('Diseño estructura &CP'!$AZ$8/GP19),0),0) -> 0
B20: =+IF(C20=0,"",B19+1) -> 5 | C20: =+E20/$H$9 -> 12 | D20: =ROUNDDOWN(E20/$C$13,0) -> 2 | E20: 24 | F20: =IF(D20=0,0,D20+1) -> 3 | G20: =IF(H20="","",1/(H20+0.01)) -> 0.024384297 | H20: =IF(E20>0,ROUNDDOWN(('Diseño estructura &CP'!$AZ$5/E20),0),"") -> 41 | J20: Lado 5 | L20: metros | N20: =IFERROR(IF(K20="",0,ROUNDDOWN(('Diseño estructura &CP'!$AZ$6/K20),0)),0) -> 0 | P20: T5 | Q20: =IF(H$11="SI",B$14,"") -> 106 | R20: =IF(Q20="","",Q20*$R$15) -> 424 | S20: =1/(T20+0.01) -> 0.99009901 | T20: =IFERROR(ROUNDDOWN(('Diseño estructura &CP'!$AZ$8/R20),0),0) -> 1 | V20: =+IF(W20=0,"",V19+1) -> 5 | W20: =+Y20/$H$9 -> 78.5 | X20: =ROUNDDOWN(Y20/$C$13,0) -> 13 | Y20: 157 | Z20: =IF(X20=0,0,X20+1) -> 14 | AA20: =IF(AB20="","",1/(AB20+0.01)) -> 0.16638935 | AB20: =IF(Y20>0,ROUNDDOWN(('Diseño estructura &CP'!$AZ$5/Y20),0),"") -> 6 | AD20: Lado 5 | AF20: metros | AH20: =IFERROR(IF(AE20="",0,ROUNDDOWN(('Diseño estructura &CP'!$AZ$6/AE20),0)),0) -> 0 | AJ20: T5 | AK20: =IF(AB$11="SI",V$14,"") -> 55 | AL20: =IF(AK20="","",AK20*$R$15) -> 220 | AM20: =1/(AN20+0.01) -> 0.49751244 | AN20: =IFERROR(ROUNDDOWN(('Diseño estructura &CP'!$AZ$8/AL20),0),0) -> 2 | AP20: =+IF(AQ20=0,"",AP19+1) -> 5 | AQ20: =+AS20/$H$9 -> 81.5 | AR20: =ROUNDDOWN(AS20/$C$13,0) -> 13 | AS20: 163 | AT20: =IF(AR20=0,0,AR20+1) -> 14 | AU20: =IF(AV20="","",1/(AV20+0.01)) -> 0.16638935 | AV20: =IF(AS20>0,ROUNDDOWN(('Diseño estructura &CP'!$AZ$5/AS20),0),"") -> 6 | AX20: Lado 5 | AZ20: metros | BB20: =IFERROR(IF(AY20="",0,ROUNDDOWN(('Diseño estructura &CP'!$AZ$6/AY20),0)),0) -> 0 | BD20: T5 | BE20: =IF(AV$11="SI",AP$14,"") -> 76 | BF20: =IF(BE20="","",BE20*$R$15) -> 304 | BG20: =1/(BH20+0.01) -> 0.99009901 | BH20: =IFERROR(ROUNDDOWN(('Diseño estructura &CP'!$AZ$8/BF20),0),0) -> 1 | BJ20: =+IF(BK20=0,"",BJ19+1) -> 5 | BK20: =+BM20/$H$9 -> 98.5 | BL20: =ROUNDDOWN(BM20/$BK$13,0) -> 17 | BM20: 197 | BN20: =IF(BL20=0,0,BL20+1) -> 18 | BO20: =IF(BP20="","",1/(BP20+0.01)) -> 0.1996008 | BP20: =IF(BM20>0,ROUNDDOWN(('Diseño estructura &CP'!$AZ$5/BM20),0),"") -> 5 | BR20: Lado 5 | BT20: metros | BV20: =IFERROR(IF(BS20="",0,ROUNDDOWN(('Diseño estructura &CP'!$AZ$6/BS20),0)),0) -> 0 | BX20: T5 | BY20: =IF(BP$11="SI",BJ$14,"") -> 30 | BZ20: =IF(BY20="","",BY20*$R$15) -> 120 | CA20: =1/(CB20+0.01) -> 0.24937656 | CB20: =IFERROR(ROUNDDOWN(('Diseño estructura &CP'!$AZ$8/BZ20),0),0) -> 4 | CD20: =+IF(CE20=0,"",CD19+1) | CE20: =+CG20/$H$9 -> 0 | CF20: =ROUNDDOWN(CG20/$C$13,0) -> 0 | CH20: =IF(CF20=0,0,CF20+1) -> 0 | CI20: =IF(CJ20="","",1/(CJ20+0.01)) | CJ20: =IF(CG20>0,ROUNDDOWN(('Diseño estructura &CP'!$AZ$5/CG20),0),"") | CL20: Lado 5 | CN20: metros | CP20: =IFERROR(IF(CM20="",0,ROUNDDOWN(('Diseño estructura &CP'!$AZ$6/CM20),0)),0) -> 0 | CR20: T5 | CS20: =IF(CJ$11="SI",CD$14,"") | CT20: =IF(CS20="","",CS20*$R$15) | CU20: =1/(CV20+0.01) -> 100 | CV20: =IFERROR(ROUNDDOWN(('Diseño estructura &CP'!$AZ$8/CT20),0),0) -> 0 | CX20: =+IF(CY20=0,"",CX19+1) | CY20: =+DA20/$H$9 -> 0 | CZ20: =ROUNDDOWN(DA20/$C$13,0) -> 0 | DB20: =IF(CZ20=0,0,CZ20+1) -> 0 | DC20: =IF(DD20="","",1/(DD20+0.01)) | DD20: =IF(DA20>0,ROUNDDOWN(('Diseño estructura &CP'!$AZ$5/DA20),0),"") | DF20: Lado 5 | DH20: metros | DJ20: =IFERROR(IF(DG20="",0,ROUNDDOWN(('Diseño estructura &CP'!$AZ$6/DG20),0)),0) -> 0 | DL20: T5 | DM20: =IF(DD$11="SI",CX$14,"") | DN20: =IF(DM20="","",DM20*$R$15) | DO20: =1/(DP20+0.01) -> 100 | DP20: =IFERROR(ROUNDDOWN(('Diseño estructura &CP'!$AZ$8/DN20),0),0) -> 0 | DR20: =+IF(DS20=0,"",DR19+1) | DS20: =+DU20/$H$9 -> 0 | DT20: =ROUNDDOWN(DU20/$C$13,0) -> 0 | DV20: =IF(DT20=0,0,DT20+1) -> 0 | DW20: =IF(DX20="","",1/(DX20+0.01)) | DX20: =IF(DU20>0,ROUNDDOWN(('Diseño estructura &CP'!$AZ$5/DU20),0),"") | DZ20: Lado 5 | EB20: metros | ED20: =IFERROR(IF(EA20="",0,ROUNDDOWN(('Diseño estructura &CP'!$AZ$6/EA20),0)),0) -> 0 | EF20: T5 | EG20: =IF(DX$11="SI",DR$14,"") | EH20: =IF(EG20="","",EG20*$R$15) | EI20: =1/(EJ20+0.01) -> 100 | EJ20: =IFERROR(ROUNDDOWN(('Diseño estructura &CP'!$AZ$8/EH20),0),0) -> 0 | EL20: =+IF(EM20=0,"",EL19+1) | EM20: =+EO20/$H$9 -> 0 | EN20: =ROUNDDOWN(EO20/$C$13,0) -> 0 | EP20: =IF(EN20=0,0,EN20+1) -> 0 | EQ20: =IF(ER20="","",1/(ER20+0.01)) | ER20: =IF(EO20>0,ROUNDDOWN(('Diseño estructura &CP'!$AZ$5/EO20),0),"") | ET20: Lado 5 | EV20: metros | EX20: =IFERROR(IF(EU20="",0,ROUNDDOWN(('Diseño estructura &CP'!$AZ$6/EU20),0)),0) -> 0 | EZ20: T5 | FA20: =IF(ER$11="SI",EL$14,"") | FB20: =IF(FA20="","",FA20*$R$15) | FC20: =1/(FD20+0.01) -> 100 | FD20: =IFERROR(ROUNDDOWN(('Diseño estructura &CP'!$AZ$8/FB20),0),0) -> 0 | FF20: =+IF(FG20=0,"",FF19+1) | FG20: =+FI20/$H$9 -> 0 | FH20: =ROUNDDOWN(FI20/$C$13,0) -> 0 | FJ20: =IF(FH20=0,0,FH20+1) -> 0 | FK20: =IF(FL20="","",1/(FL20+0.01)) | FL20: =IF(FI20>0,ROUNDDOWN(('Diseño estructura &CP'!$AZ$5/FI20),0),"") | FN20: Lado 5 | FP20: metros | FR20: =IFERROR(IF(FO20="",0,ROUNDDOWN(('Diseño estructura &CP'!$AZ$6/FO20),0)),0) -> 0 | FT20: T5 | FU20: =IF(FL$11="SI",FF$14,"") | FV20: =IF(FU20="","",FU20*$R$15) | FW20: =1/(FX20+0.01) -> 100 | FX20: =IFERROR(ROUNDDOWN(('Diseño estructura &CP'!$AZ$8/FV20),0),0) -> 0 | FZ20: =+IF(GA20=0,"",FZ19+1) | GA20: =+GC20/$H$9 -> 0 | GB20: =ROUNDDOWN(GC20/$C$13,0) -> 0 | GD20: =IF(GB20=0,0,GB20+1) -> 0 | GE20: =IF(GF20="","",1/(GF20+0.01)) | GF20: =IF(GC20>0,ROUNDDOWN(('Diseño estructura &CP'!$AZ$5/GC20),0),"") | GH20: Lado 5 | GJ20: metros | GL20: =IFERROR(IF(GI20="",0,ROUNDDOWN(('Diseño estructura &CP'!$AZ$6/GI20),0)),0) -> 0 | GN20: T5 | GO20: =IF(GF$11="SI",FZ$14,"") | GP20: =IF(GO20="","",GO20*$R$15) | GQ20: =1/(GR20+0.01) -> 100 | GR20: =IFERROR(ROUNDDOWN(('Diseño estructura &CP'!$AZ$8/GP20),0),0) -> 0
B21: =+IF(C21=0,"",B20+1) -> 6 | C21: =+E21/$H$9 -> 15 | D21: =ROUNDDOWN(E21/$C$13,0) -> 2 | E21: 30 | F21: =IF(D21=0,0,D21+1) -> 3 | G21: =IF(H21="","",1/(H21+0.01)) -> 0.03029385 | H21: =IF(E21>0,ROUNDDOWN(('Diseño estructura &CP'!$AZ$5/E21),0),"") -> 33 | J21: Lado 6 | L21: metros | N21: =IFERROR(IF(K21="",0,ROUNDDOWN(('Diseño estructura &CP'!$AZ$6/K21),0)),0) -> 0 | P21: T6 | Q21: =IF(H$11="SI",B$14,"") -> 106 | R21: =IF(Q21="","",Q21*$R$15) -> 424 | S21: =1/(T21+0.01) -> 0.99009901 | T21: =IFERROR(ROUNDDOWN(('Diseño estructura &CP'!$AZ$8/R21),0),0) -> 1 | V21: =+IF(W21=0,"",V20+1) -> 6 | W21: =+Y21/$H$9 -> 79.5 | X21: =ROUNDDOWN(Y21/$C$13,0) -> 13 | Y21: 159 | Z21: =IF(X21=0,0,X21+1) -> 14 | AA21: =IF(AB21="","",1/(AB21+0.01)) -> 0.16638935 | AB21: =IF(Y21>0,ROUNDDOWN(('Diseño estructura &CP'!$AZ$5/Y21),0),"") -> 6 | AD21: Lado 6 | AF21: metros | AH21: =IFERROR(IF(AE21="",0,ROUNDDOWN(('Diseño estructura &CP'!$AZ$6/AE21),0)),0) -> 0 | AJ21: T6 | AK21: =IF(AB$11="SI",V$14,"") -> 55 | AL21: =IF(AK21="","",AK21*$R$15) -> 220 | AM21: =1/(AN21+0.01) -> 0.49751244 | AN21: =IFERROR(ROUNDDOWN(('Diseño estructura &CP'!$AZ$8/AL21),0),0) -> 2 | AP21: =+IF(AQ21=0,"",AP20+1) -> 6 | AQ21: =+AS21/$H$9 -> 81.75 | AR21: =ROUNDDOWN(AS21/$C$13,0) -> 13 | AS21: 163.5 | AT21: =IF(AR21=0,0,AR21+1) -> 14 | AU21: =IF(AV21="","",1/(AV21+0.01)) -> 0.16638935 | AV21: =IF(AS21>0,ROUNDDOWN(('Diseño estructura &CP'!$AZ$5/AS21),0),"") -> 6 | AX21: Lado 6 | AZ21: metros | BB21: =IFERROR(IF(AY21="",0,ROUNDDOWN(('Diseño estructura &CP'!$AZ$6/AY21),0)),0) -> 0 | BD21: T6 | BE21: =IF(AV$11="SI",AP$14,"") -> 76 | BF21: =IF(BE21="","",BE21*$R$15) -> 304 | BG21: =1/(BH21+0.01) -> 0.99009901 | BH21: =IFERROR(ROUNDDOWN(('Diseño estructura &CP'!$AZ$8/BF21),0),0) -> 1 | BJ21: =+IF(BK21=0,"",BJ20+1) -> 6 | BK21: =+BM21/$H$9 -> 98.5 | BL21: =ROUNDDOWN(BM21/$BK$13,0) -> 17 | BM21: 197 | BN21: =IF(BL21=0,0,BL21+1) -> 18 | BO21: =IF(BP21="","",1/(BP21+0.01)) -> 0.1996008 | BP21: =IF(BM21>0,ROUNDDOWN(('Diseño estructura &CP'!$AZ$5/BM21),0),"") -> 5 | BR21: Lado 6 | BT21: metros | BV21: =IFERROR(IF(BS21="",0,ROUNDDOWN(('Diseño estructura &CP'!$AZ$6/BS21),0)),0) -> 0 | BX21: T6 | BY21: =IF(BP$11="SI",BJ$14,"") -> 30 | BZ21: =IF(BY21="","",BY21*$R$15) -> 120 | CA21: =1/(CB21+0.01) -> 0.24937656 | CB21: =IFERROR(ROUNDDOWN(('Diseño estructura &CP'!$AZ$8/BZ21),0),0) -> 4 | CD21: =+IF(CE21=0,"",CD20+1) | CE21: =+CG21/$H$9 -> 0 | CF21: =ROUNDDOWN(CG21/$C$13,0) -> 0 | CH21: =IF(CF21=0,0,CF21+1) -> 0 | CI21: =IF(CJ21="","",1/(CJ21+0.01)) | CJ21: =IF(CG21>0,ROUNDDOWN(('Diseño estructura &CP'!$AZ$5/CG21),0),"") | CL21: Lado 6 | CN21: metros | CP21: =IFERROR(IF(CM21="",0,ROUNDDOWN(('Diseño estructura &CP'!$AZ$6/CM21),0)),0) -> 0 | CR21: T6 | CS21: =IF(CJ$11="SI",CD$14,"") | CT21: =IF(CS21="","",CS21*$R$15) | CU21: =1/(CV21+0.01) -> 100 | CV21: =IFERROR(ROUNDDOWN(('Diseño estructura &CP'!$AZ$8/CT21),0),0) -> 0 | CX21: =+IF(CY21=0,"",CX20+1) | CY21: =+DA21/$H$9 -> 0 | CZ21: =ROUNDDOWN(DA21/$C$13,0) -> 0 | DB21: =IF(CZ21=0,0,CZ21+1) -> 0 | DC21: =IF(DD21="","",1/(DD21+0.01)) | DD21: =IF(DA21>0,ROUNDDOWN(('Diseño estructura &CP'!$AZ$5/DA21),0),"") | DF21: Lado 6 | DH21: metros | DJ21: =IFERROR(IF(DG21="",0,ROUNDDOWN(('Diseño estructura &CP'!$AZ$6/DG21),0)),0) -> 0 | DL21: T6 | DM21: =IF(DD$11="SI",CX$14,"") | DN21: =IF(DM21="","",DM21*$R$15) | DO21: =1/(DP21+0.01) -> 100 | DP21: =IFERROR(ROUNDDOWN(('Diseño estructura &CP'!$AZ$8/DN21),0),0) -> 0 | DR21: =+IF(DS21=0,"",DR20+1) | DS21: =+DU21/$H$9 -> 0 | DT21: =ROUNDDOWN(DU21/$C$13,0) -> 0 | DV21: =IF(DT21=0,0,DT21+1) -> 0 | DW21: =IF(DX21="","",1/(DX21+0.01)) | DX21: =IF(DU21>0,ROUNDDOWN(('Diseño estructura &CP'!$AZ$5/DU21),0),"") | DZ21: Lado 6 | EB21: metros | ED21: =IFERROR(IF(EA21="",0,ROUNDDOWN(('Diseño estructura &CP'!$AZ$6/EA21),0)),0) -> 0 | EF21: T6 | EG21: =IF(DX$11="SI",DR$14,"") | EH21: =IF(EG21="","",EG21*$R$15) | EI21: =1/(EJ21+0.01) -> 100 | EJ21: =IFERROR(ROUNDDOWN(('Diseño estructura &CP'!$AZ$8/EH21),0),0) -> 0 | EL21: =+IF(EM21=0,"",EL20+1) | EM21: =+EO21/$H$9 -> 0 | EN21: =ROUNDDOWN(EO21/$C$13,0) -> 0 | EP21: =IF(EN21=0,0,EN21+1) -> 0 | EQ21: =IF(ER21="","",1/(ER21+0.01)) | ER21: =IF(EO21>0,ROUNDDOWN(('Diseño estructura &CP'!$AZ$5/EO21),0),"") | ET21: Lado 6 | EV21: metros | EX21: =IFERROR(IF(EU21="",0,ROUNDDOWN(('Diseño estructura &CP'!$AZ$6/EU21),0)),0) -> 0 | EZ21: T6 | FA21: =IF(ER$11="SI",EL$14,"") | FB21: =IF(FA21="","",FA21*$R$15) | FC21: =1/(FD21+0.01) -> 100 | FD21: =IFERROR(ROUNDDOWN(('Diseño estructura &CP'!$AZ$8/FB21),0),0) -> 0 | FF21: =+IF(FG21=0,"",FF20+1) | FG21: =+FI21/$H$9 -> 0 | FH21: =ROUNDDOWN(FI21/$C$13,0) -> 0 | FJ21: =IF(FH21=0,0,FH21+1) -> 0 | FK21: =IF(FL21="","",1/(FL21+0.01)) | FL21: =IF(FI21>0,ROUNDDOWN(('Diseño estructura &CP'!$AZ$5/FI21),0),"") | FN21: Lado 6 | FP21: metros | FR21: =IFERROR(IF(FO21="",0,ROUNDDOWN(('Diseño estructura &CP'!$AZ$6/FO21),0)),0) -> 0 | FT21: T6 | FU21: =IF(FL$11="SI",FF$14,"") | FV21: =IF(FU21="","",FU21*$R$15) | FW21: =1/(FX21+0.01) -> 100 | FX21: =IFERROR(ROUNDDOWN(('Diseño estructura &CP'!$AZ$8/FV21),0),0) -> 0 | FZ21: =+IF(GA21=0,"",FZ20+1) | GA21: =+GC21/$H$9 -> 0 | GB21: =ROUNDDOWN(GC21/$C$13,0) -> 0 | GD21: =IF(GB21=0,0,GB21+1) -> 0 | GE21: =IF(GF21="","",1/(GF21+0.01)) | GF21: =IF(GC21>0,ROUNDDOWN(('Diseño estructura &CP'!$AZ$5/GC21),0),"") | GH21: Lado 6 | GJ21: metros | GL21: =IFERROR(IF(GI21="",0,ROUNDDOWN(('Diseño estructura &CP'!$AZ$6/GI21),0)),0) -> 0 | GN21: T6 | GO21: =IF(GF$11="SI",FZ$14,"") | GP21: =IF(GO21="","",GO21*$R$15) | GQ21: =1/(GR21+0.01) -> 100 | GR21: =IFERROR(ROUNDDOWN(('Diseño estructura &CP'!$AZ$8/GP21),0),0) -> 0
